Traceback (most recent call last):
  File "/sc-projects/sc-proj-dh-ukb-intergenics/envs/networkvi_py310/lib/python3.10/site-packages/jupyter_core/utils/__init__.py", line 154, in wrapped
    asyncio.get_running_loop()
RuntimeError: no running event loop

During handling of the above exception, another exception occurred:

Traceback (most recent call last):
  File "/sc-projects/sc-proj-dh-ukb-intergenics/envs/networkvi_py310/lib/python3.10/site-packages/jupyter_cache/executors/utils.py", line 58, in single_nb_execution
    executenb(
  File "/sc-projects/sc-proj-dh-ukb-intergenics/envs/networkvi_py310/lib/python3.10/site-packages/nbclient/client.py", line 1319, in execute
    return NotebookClient(nb=nb, resources=resources, km=km, **kwargs).execute()
  File "/sc-projects/sc-proj-dh-ukb-intergenics/envs/networkvi_py310/lib/python3.10/site-packages/jupyter_core/utils/__init__.py", line 158, in wrapped
    return loop.run_until_complete(inner)
  File "/sc-projects/sc-proj-dh-ukb-intergenics/envs/networkvi_py310/lib/python3.10/asyncio/base_events.py", line 649, in run_until_complete
    return future.result()
  File "/sc-projects/sc-proj-dh-ukb-intergenics/envs/networkvi_py310/lib/python3.10/site-packages/nbclient/client.py", line 709, in async_execute
    await self.async_execute_cell(
  File "/sc-projects/sc-proj-dh-ukb-intergenics/envs/networkvi_py310/lib/python3.10/site-packages/nbclient/client.py", line 1062, in async_execute_cell
    await self._check_raise_for_error(cell, cell_index, exec_reply)
  File "/sc-projects/sc-proj-dh-ukb-intergenics/envs/networkvi_py310/lib/python3.10/site-packages/nbclient/client.py", line 918, in _check_raise_for_error
    raise CellExecutionError.from_cell_and_msg(cell, exec_reply_content)
nbclient.exceptions.CellExecutionError: An error occurred while executing the following cell:
------------------
import numpy as np
import requests
import sys
sys.path.append("../../../src")
import scvi
from networkvi.model import NETWORKVI
import scanpy as sc
import anndata as ad
import matplotlib.pyplot as plt
from sklearn.ensemble import RandomForestClassifier
import sklearn
from sklearn.preprocessing import normalize
import seaborn as sns
import pandas as pd
from goatools.obo_parser import GODag
import shutil
------------------


[0;31m---------------------------------------------------------------------------[0m
[0;31mModuleNotFoundError[0m                       Traceback (most recent call last)
Cell [0;32mIn[2], line 5[0m
[1;32m      3[0m [38;5;28;01mimport[39;00m [38;5;21;01msys[39;00m
[1;32m      4[0m sys[38;5;241m.[39mpath[38;5;241m.[39mappend([38;5;124m"[39m[38;5;124m../../../src[39m[38;5;124m"[39m)
[0;32m----> 5[0m [38;5;28;01mimport[39;00m [38;5;21;01mscvi[39;00m
[1;32m      6[0m [38;5;28;01mfrom[39;00m [38;5;21;01mnetworkvi[39;00m[38;5;21;01m.[39;00m[38;5;21;01mmodel[39;00m [38;5;28;01mimport[39;00m NETWORKVI
[1;32m      7[0m [38;5;28;01mimport[39;00m [38;5;21;01mscanpy[39;00m [38;5;28;01mas[39;00m [38;5;21;01msc[39;00m

[0;31mModuleNotFoundError[0m: No module named 'scvi'

